[2024-04-04T16:19:08.271+0000] {taskinstance.py:1979} INFO - Dependencies all met for dep_context=non-requeueable deps ti=<TaskInstance: callback.error_print manual__2024-04-04T16:19:06.980030+00:00 [queued]>
[2024-04-04T16:19:08.276+0000] {taskinstance.py:1979} INFO - Dependencies all met for dep_context=requeueable deps ti=<TaskInstance: callback.error_print manual__2024-04-04T16:19:06.980030+00:00 [queued]>
[2024-04-04T16:19:08.277+0000] {taskinstance.py:2193} INFO - Starting attempt 1 of 1
[2024-04-04T16:19:08.288+0000] {taskinstance.py:2214} INFO - Executing <Task(PythonOperator): error_print> on 2024-04-04 16:19:06.980030+00:00
[2024-04-04T16:19:08.291+0000] {standard_task_runner.py:60} INFO - Started process 57 to run task
[2024-04-04T16:19:08.294+0000] {standard_task_runner.py:87} INFO - Running: ['***', 'tasks', 'run', 'callback', 'error_print', 'manual__2024-04-04T16:19:06.980030+00:00', '--job-id', '231', '--raw', '--subdir', 'DAGS_FOLDER/callback.py', '--cfg-path', '/tmp/tmpwrun5o64']
[2024-04-04T16:19:08.295+0000] {standard_task_runner.py:88} INFO - Job 231: Subtask error_print
[2024-04-04T16:19:08.363+0000] {task_command.py:423} INFO - Running <TaskInstance: callback.error_print manual__2024-04-04T16:19:06.980030+00:00 [running]> on host 50f748820a54
[2024-04-04T16:19:08.509+0000] {taskinstance.py:2510} INFO - Exporting env vars: AIRFLOW_CTX_DAG_OWNER='vutt' AIRFLOW_CTX_DAG_ID='callback' AIRFLOW_CTX_TASK_ID='error_print' AIRFLOW_CTX_EXECUTION_DATE='2024-04-04T16:19:06.980030+00:00' AIRFLOW_CTX_TRY_NUMBER='1' AIRFLOW_CTX_DAG_RUN_ID='manual__2024-04-04T16:19:06.980030+00:00'
[2024-04-04T16:19:08.509+0000] {taskinstance.py:2593} ERROR - Failed when executing execute callback
Traceback (most recent call last):
  File "/home/airflow/.local/lib/python3.11/site-packages/airflow/models/taskinstance.py", line 2591, in _run_execute_callback
    callback(context)
  File "/opt/airflow/dags/callback.py", line 12, in _executed_alert
    print(f"executed at {(context['ti'].queued_at).astimezone(hcm_tz).strftime('%Y-%m-%d %H:%M:%S')}")
                          ^^^^^^^^^^^^^^^^^^^^^^^
AttributeError: 'TaskInstance' object has no attribute 'queued_at'
[2024-04-04T16:19:08.512+0000] {taskinstance.py:2728} ERROR - Task failed with exception
Traceback (most recent call last):
  File "/home/airflow/.local/lib/python3.11/site-packages/airflow/models/taskinstance.py", line 444, in _execute_task
    result = _execute_callable(context=context, **execute_callable_kwargs)
             ^^^^^^^^^^^^^^^^^^^^^^^^^^^^^^^^^^^^^^^^^^^^^^^^^^^^^^^^^^^^^
  File "/home/airflow/.local/lib/python3.11/site-packages/airflow/models/taskinstance.py", line 414, in _execute_callable
    return execute_callable(context=context, **execute_callable_kwargs)
           ^^^^^^^^^^^^^^^^^^^^^^^^^^^^^^^^^^^^^^^^^^^^^^^^^^^^^^^^^^^^
  File "/home/airflow/.local/lib/python3.11/site-packages/airflow/operators/python.py", line 200, in execute
    return_value = self.execute_callable()
                   ^^^^^^^^^^^^^^^^^^^^^^^
  File "/home/airflow/.local/lib/python3.11/site-packages/airflow/operators/python.py", line 217, in execute_callable
    return self.python_callable(*self.op_args, **self.op_kwargs)
           ^^^^^^^^^^^^^^^^^^^^^^^^^^^^^^^^^^^^^^^^^^^^^^^^^^^^^
  File "/opt/airflow/dags/callback.py", line 9, in _error_print
    print(context['dss'])
          ~~~~~~~^^^^^^^
KeyError: 'dss'
[2024-04-04T16:19:08.532+0000] {taskinstance.py:1149} INFO - Marking task as FAILED. dag_id=callback, task_id=error_print, execution_date=20240404T161906, start_date=20240404T161908, end_date=20240404T161908
[2024-04-04T16:19:08.532+0000] {taskinstance.py:1127} ERROR - Error when executing _failed_alert callback
Traceback (most recent call last):
  File "/home/airflow/.local/lib/python3.11/site-packages/airflow/models/taskinstance.py", line 2357, in _run_raw_task
    self._execute_task_with_callbacks(context, test_mode, session=session)
  File "/home/airflow/.local/lib/python3.11/site-packages/airflow/models/taskinstance.py", line 2529, in _execute_task_with_callbacks
    result = self._execute_task(context, task_orig)
             ^^^^^^^^^^^^^^^^^^^^^^^^^^^^^^^^^^^^^^
  File "/home/airflow/.local/lib/python3.11/site-packages/airflow/models/taskinstance.py", line 2546, in _execute_task
    return _execute_task(self, context, task_orig)
           ^^^^^^^^^^^^^^^^^^^^^^^^^^^^^^^^^^^^^^^
  File "/home/airflow/.local/lib/python3.11/site-packages/airflow/models/taskinstance.py", line 444, in _execute_task
    result = _execute_callable(context=context, **execute_callable_kwargs)
             ^^^^^^^^^^^^^^^^^^^^^^^^^^^^^^^^^^^^^^^^^^^^^^^^^^^^^^^^^^^^^
  File "/home/airflow/.local/lib/python3.11/site-packages/airflow/models/taskinstance.py", line 414, in _execute_callable
    return execute_callable(context=context, **execute_callable_kwargs)
           ^^^^^^^^^^^^^^^^^^^^^^^^^^^^^^^^^^^^^^^^^^^^^^^^^^^^^^^^^^^^
  File "/home/airflow/.local/lib/python3.11/site-packages/airflow/operators/python.py", line 200, in execute
    return_value = self.execute_callable()
                   ^^^^^^^^^^^^^^^^^^^^^^^
  File "/home/airflow/.local/lib/python3.11/site-packages/airflow/operators/python.py", line 217, in execute_callable
    return self.python_callable(*self.op_args, **self.op_kwargs)
           ^^^^^^^^^^^^^^^^^^^^^^^^^^^^^^^^^^^^^^^^^^^^^^^^^^^^^
  File "/opt/airflow/dags/callback.py", line 9, in _error_print
    print(context['dss'])
          ~~~~~~~^^^^^^^
KeyError: 'dss'

During handling of the above exception, another exception occurred:

Traceback (most recent call last):
  File "/home/airflow/.local/lib/python3.11/site-packages/airflow/models/taskinstance.py", line 1124, in _run_finished_callback
    callback(context)
  File "/opt/airflow/dags/callback.py", line 18, in _failed_alert
    print(f"failed at {(context['ti'].queued_at).astimezone(hcm_tz).strftime('%Y-%m-%d %H:%M:%S')}")
                        ^^^^^^^^^^^^^^^^^^^^^^^
AttributeError: 'TaskInstance' object has no attribute 'queued_at'
[2024-04-04T16:19:08.593+0000] {standard_task_runner.py:107} ERROR - Failed to execute job 231 for task error_print ('dss'; 57)
[2024-04-04T16:19:08.627+0000] {local_task_job_runner.py:234} INFO - Task exited with return code 1
[2024-04-04T16:19:08.674+0000] {taskinstance.py:3309} INFO - 0 downstream tasks scheduled from follow-on schedule check
