[2024-04-04T16:23:43.563+0000] {taskinstance.py:1979} INFO - Dependencies all met for dep_context=non-requeueable deps ti=<TaskInstance: callback.error_print manual__2024-04-04T16:19:06.980030+00:00 [queued]>
[2024-04-04T16:23:43.569+0000] {taskinstance.py:1979} INFO - Dependencies all met for dep_context=requeueable deps ti=<TaskInstance: callback.error_print manual__2024-04-04T16:19:06.980030+00:00 [queued]>
[2024-04-04T16:23:43.570+0000] {taskinstance.py:2193} INFO - Starting attempt 2 of 2
[2024-04-04T16:23:43.587+0000] {taskinstance.py:2214} INFO - Executing <Task(PythonOperator): error_print> on 2024-04-04 16:19:06.980030+00:00
[2024-04-04T16:23:43.591+0000] {standard_task_runner.py:60} INFO - Started process 122 to run task
[2024-04-04T16:23:43.593+0000] {standard_task_runner.py:87} INFO - Running: ['***', 'tasks', 'run', 'callback', 'error_print', 'manual__2024-04-04T16:19:06.980030+00:00', '--job-id', '232', '--raw', '--subdir', 'DAGS_FOLDER/callback.py', '--cfg-path', '/tmp/tmpv1mnhosh']
[2024-04-04T16:23:43.594+0000] {standard_task_runner.py:88} INFO - Job 232: Subtask error_print
[2024-04-04T16:23:43.663+0000] {task_command.py:423} INFO - Running <TaskInstance: callback.error_print manual__2024-04-04T16:19:06.980030+00:00 [running]> on host 50f748820a54
[2024-04-04T16:23:43.770+0000] {taskinstance.py:2510} INFO - Exporting env vars: AIRFLOW_CTX_DAG_OWNER='vutt' AIRFLOW_CTX_DAG_ID='callback' AIRFLOW_CTX_TASK_ID='error_print' AIRFLOW_CTX_EXECUTION_DATE='2024-04-04T16:19:06.980030+00:00' AIRFLOW_CTX_TRY_NUMBER='2' AIRFLOW_CTX_DAG_RUN_ID='manual__2024-04-04T16:19:06.980030+00:00'
[2024-04-04T16:23:43.771+0000] {logging_mixin.py:188} INFO - executed at 2024-04-04 23:23:42
[2024-04-04T16:23:43.771+0000] {taskinstance.py:2728} ERROR - Task failed with exception
Traceback (most recent call last):
  File "/home/airflow/.local/lib/python3.11/site-packages/airflow/models/taskinstance.py", line 444, in _execute_task
    result = _execute_callable(context=context, **execute_callable_kwargs)
             ^^^^^^^^^^^^^^^^^^^^^^^^^^^^^^^^^^^^^^^^^^^^^^^^^^^^^^^^^^^^^
  File "/home/airflow/.local/lib/python3.11/site-packages/airflow/models/taskinstance.py", line 414, in _execute_callable
    return execute_callable(context=context, **execute_callable_kwargs)
           ^^^^^^^^^^^^^^^^^^^^^^^^^^^^^^^^^^^^^^^^^^^^^^^^^^^^^^^^^^^^
  File "/home/airflow/.local/lib/python3.11/site-packages/airflow/operators/python.py", line 200, in execute
    return_value = self.execute_callable()
                   ^^^^^^^^^^^^^^^^^^^^^^^
  File "/home/airflow/.local/lib/python3.11/site-packages/airflow/operators/python.py", line 217, in execute_callable
    return self.python_callable(*self.op_args, **self.op_kwargs)
           ^^^^^^^^^^^^^^^^^^^^^^^^^^^^^^^^^^^^^^^^^^^^^^^^^^^^^
  File "/opt/airflow/dags/callback.py", line 9, in _error_print
    print(context['dss'])
          ~~~~~~~^^^^^^^
KeyError: 'dss'
[2024-04-04T16:23:43.790+0000] {taskinstance.py:1149} INFO - Marking task as FAILED. dag_id=callback, task_id=error_print, execution_date=20240404T161906, start_date=20240404T162343, end_date=20240404T162343
[2024-04-04T16:23:43.790+0000] {logging_mixin.py:188} INFO - failed at 2024-04-04 23:23:42
[2024-04-04T16:23:43.803+0000] {standard_task_runner.py:107} ERROR - Failed to execute job 232 for task error_print ('dss'; 122)
[2024-04-04T16:23:43.845+0000] {local_task_job_runner.py:234} INFO - Task exited with return code 1
[2024-04-04T16:23:43.871+0000] {taskinstance.py:3309} INFO - 0 downstream tasks scheduled from follow-on schedule check
